Workbook

Sheet PROJECT DETAILS
A1: DETAILS
A2: PROJECT TITLE | B2: ONE STOREY RESIDENTIAL BUILDING
A3: LOCATION | B3: BARANGAY BENITEZ, BANGA, SOUTH COTABATO
A4: DURATION | B4: 200
A5: CONTRACTOR | B5: GEMMA CONSTRUCTION
A6: PROJECT SOURCE | B6: SLF 2018
A8: C1 | E8: C2 | I8: C3 | M8: C4 | Q8: C5
A10: Hbc= | B10: 2.5 | C10: m | E10: Hbc= | F10: 2 | G10: m | I10: Hbc= | J10: 0.55 | K10: m | M10: Hbc= | N10: 0.55 | O10: m
A11: L= | B11: 0.7 | C11: m | E11: L= | F11: 0.6 | G11: m | I11: L= | J11: 0.35 | K11: m | M11: L= | N11: 0.35 | O11: m | Q11: L= | R11: 1 | S11: m
A12: W= | B12: 1.1 | C12: m | E12: W= | F12: 0.6 | G12: m | I12: W= | J12: 0.35 | K12: m | M12: W= | N12: 0.35 | O12: m | Q12: W= | S12: m
A13: H= | B13: 3.6 | C13: m | E13: H= | F13: 1.2 | G13: m | I13: H= | J13: 3 | K13: m | M13: H= | N13: 3 | O13: m | Q13: H= | S13: m
A14: NO. OF PCS = | B14: 10 | C14: pcs | E14: NO. OF PCS = | F14: 20 | G14: pcs | I14: NO. OF PCS = | J14: 9 | K14: pcs | M14: NO. OF PCS = | N14: 9 | O14: pcs | Q14: NO. OF PCS = | S14: pcs
A15: V= | B15: =B13*B12*B11*B14 -> 27.72 | C15: cu.m. | E15: V= | F15: =F13*F12*F11*F14 -> 8.64 | G15: cu.m. | I15: V= | J15: =J13*J12*J11*J14 -> 3.3075 | K15: cu.m. | M15: V= | N15: =N13*N12*N11*N14 -> 3.3075 | O15: cu.m. | Q15: V= | R15: =R13*R12*R11*R14 -> 0 | S15: cu.m.
A16: BAR SIZE = | B16: 20 | C16: mm | E16: BAR SIZE = | F16: 20 | G16: mm | I16: BAR SIZE = | J16: 12 | K16: mm | M16: BAR SIZE = | N16: 12 | O16: mm
A17: NO.OF BAR | E17: NO.OF BAR | I17: NO.OF BAR | M17: NO.OF BAR
A18: PER ONE | B18: 14 | C18: pcs | E18: PER ONE | F18: 12 | G18: pcs | I18: PER ONE | J18: 4 | K18: pcs | M18: PER ONE | N18: 4 | O18: pcs
A19: COLUMN | E19: COLUMN | I19: COLUMN | M19: COLUMN
A21: lateral ties | E21: lateral ties | I21: lateral ties | M21: lateral ties
A22: BAR SIZE = | B22: 10 | C22: mm | E22: BAR SIZE = | F22: 10 | G22: mm | I22: BAR SIZE = | J22: 0 | K22: mm | M22: BAR SIZE = | N22: 0 | O22: mm
A23: n1= | B23: 5 | C23: s1= | D23: 0.05 | E23: n1= | F23: 5 | G23: s1= | H23: 0.05 | I23: n1= | J23: 0 | K23: s1= | L23: 0 | M23: n1= | N23: 0 | O23: s1= | P23: 0
A24: n2= | B24: 5 | C24: s2= | D24: 0.1 | E24: n2= | F24: 5 | G24: s2= | H24: 0.1 | I24: n2= | J24: 0 | K24: s2= | L24: 0 | M24: n2= | N24: 0 | O24: s2= | P24: 0
A25: n3= | B25: 5 | C25: s3= | D25: 0.15 | E25: n3= | F25: 0 | G25: s3= | H25: 0 | I25: n3= | J25: 0 | K25: s3= | L25: 0 | M25: n3= | N25: 0 | O25: s3= | P25: 0
A26: n4= | B26: 0 | C26: s4= | D26: 0 | E26: n4= | F26: 0 | G26: s4= | H26: 0 | I26: n4= | J26: 0 | K26: s4= | L26: 0 | M26: n4= | N26: 0 | O26: s4= | P26: 0
C27: s5= | D27: 0.2 | G27: s5= | H27: 0.2 | K27: s5= | L27: 0 | O27: s5= | P27: 0
A32: F1 | E32: F2 | I32: F3 | M32: F4 | Q32: F5
A34: Hb= | B34: =B10+B37+0.05 -> 3.35 | C34: m | E34: Hb= | F34: =F10+F37+0.05 -> 2.65 | G34: m | I34: Hb= | J34: =J10+J37+0.05 -> 0.85 | K34: m | M34: Hb= | N34: =N10+N37+0.05 -> 0.85 | O34: m
A35: L= | B35: 3 | C35: m | E35: L= | F35: 2 | G35: m | I35: L= | J35: 1 | K35: m | M35: L= | N35: 1 | O35: m | Q35: L= | S35: m
A36: W= | B36: 3 | C36: m | E36: W= | F36: 2 | G36: m | I36: W= | J36: 1 | K36: m | M36: W= | N36: 1 | O36: m | Q36: W= | S36: m
A37: T= | B37: 0.8 | C37: m | E37: T= | F37: 0.6 | G37: m | I37: T= | J37: 0.25 | K37: m | M37: T= | N37: 0.25 | O37: m | Q37: H= | S37: m
A38: NO. OF PCS = | B38: 10 | C38: pcs | E38: NO. OF PCS = | F38: 20 | G38: pcs | I38: NO. OF PCS = | J38: 20 | K38: pcs | M38: NO. OF PCS = | N38: 20 | O38: pcs | Q38: NO. OF PCS = | S38: pcs
A39: V= | B39: =B37*B36*B35*B38 -> 72 | C39: cu.m. | E39: V= | F39: =F37*F36*F35*F38 -> 48 | G39: cu.m. | I39: V= | J39: =J37*J36*J35*J38 -> 5 | K39: cu.m. | M39: V= | N39: =N37*N36*N35*N38 -> 5 | O39: cu.m. | Q39: V= | R39: =R37*R36*R35*R38 -> 0 | S39: cu.m.
A40: BAR SIZE= | B40: 12 | C40: mm | E40: BAR SIZE= | F40: 12 | G40: mm | I40: BAR SIZE= | J40: 12 | K40: mm | M40: BAR SIZE= | N40: 12 | O40: mm
A41: NO.OF BAR | C41: pcs | E41: NO.OF BAR | G41: pcs | I41: NO.OF BAR | K41: pcs | M41: NO.OF BAR | O41: pcs
A42: PER ONE | B42: 5 | E42: PER ONE | F42: 5 | I42: PER ONE | J42: 5 | M42: PER ONE | N42: 5
A43: FOOTING L | E43: FOOTING | I43: FOOTING | M43: FOOTING
A44: NO.OF BAR | C44: pcs | E44: NO.OF BAR | G44: pcs | I44: NO.OF BAR | K44: pcs | M44: NO.OF BAR | O44: pcs
A45: PER ONE | B45: 5 | E45: PER ONE | F45: 5 | I45: PER ONE | J45: 5 | M45: PER ONE | N45: 5
A46: FOOTING W | E46: FOOTING 2 | I46: FOOTING 2 | M46: FOOTING 2
A52: TIE BEAM 1 | E52: TIE BEAM 2 | I52: TIE BEAM 3 | M52: TIE BEAM 4
A54: Total P.= | B54: 40 | C54: m | E54: Total P.= | F54: 50 | G54: m | I54: Total P.= | J54: 51.4 | K54: m | M54: Total P.= | N54: 51.4 | O54: m
...

Sheet ESTIMATES
A1: ESTIMATES MATERIALS
A3: STRUCTURAL EXCAVATION
A5: Vse = (VOLUME OF CF + TB) +SP + CB
A6: Vse = | B6: =(SUM(C13,H13,M13,R13,D20,J20,P20,V20))+C23+(SUM(C31,I31,O31)) -> 2038.388 | C6: CU.M.
A8: C1F1 | F8: C2F2 | K8: C3F3 | P8: C4F4
B9: L+.25= | C9: ='PROJECT DETAILS'!B35+0.25 -> 3.25 | D9: m | G9: L+.25= | H9: ='PROJECT DETAILS'!F35+0.25 -> 2.25 | I9: m | L9: L+.25= | M9: ='PROJECT DETAILS'!J35+0.25 -> 1.25 | N9: m | Q9: L+.25= | R9: ='PROJECT DETAILS'!N35+0.25 -> 1.25 | S9: m
B10: W+.25= | C10: ='PROJECT DETAILS'!B36+0.25 -> 3.25 | D10: m | G10: W+.25= | H10: ='PROJECT DETAILS'!F36+0.25 -> 2.25 | I10: m | L10: W+.25= | M10: ='PROJECT DETAILS'!J35+0.25 -> 1.25 | N10: m | Q10: W+.25= | R10: ='PROJECT DETAILS'!N36+0.25 -> 1.25 | S10: m
B11: Hb= | C11: ='PROJECT DETAILS'!B34 -> 3.35 | D11: m | G11: Hb= | H11: ='PROJECT DETAILS'!F34 -> 2.65 | I11: m | L11: Hb= | M11: ='PROJECT DETAILS'!J34 -> 0.85 | N11: m | Q11: Hb= | R11: ='PROJECT DETAILS'!N34 -> 0.85 | S11: m
B12: NO.OF PCS= | C12: ='PROJECT DETAILS'!B38 -> 10 | D12: pcs | G12: NO.OF PCS= | H12: ='PROJECT DETAILS'!F38 -> 20 | I12: pcs | L12: NO.OF PCS= | M12: ='PROJECT DETAILS'!J38 -> 20 | N12: pcs | Q12: NO.OF PCS= | R12: ='PROJECT DETAILS'!N38 -> 20 | S12: pcs
B13: V= | C13: =C11*C10*C9*C12 -> 353.84375 | D13: m | G13: V= | H13: =H11*H10*H9*H12 -> 268.3125 | I13: m | L13: V= | M13: =M11*M10*M9*M12 -> 26.5625 | N13: m | Q13: V= | R13: =R11*R10*R9*R12 -> 26.5625 | S13: m
A15: TIE BEAM 1 | G15: TIE BEAM 2 | M15: TIE BEAM 3 | S15: TIE BEAM 4
C16: Total P.= | D16: ='PROJECT DETAILS'!B54 -> 40 | E16: m | I16: Total P.= | J16: ='PROJECT DETAILS'!F54 -> 50 | K16: m | O16: Total P.= | P16: ='PROJECT DETAILS'!J54 -> 51.4 | Q16: m | U16: Total P.= | V16: ='PROJECT DETAILS'!N54 -> 51.4 | W16: m
C17: W= | D17: ='PROJECT DETAILS'!B55 -> 0.4 | E17: m | I17: W= | J17: ='PROJECT DETAILS'!F55 -> 0.3 | K17: m | O17: W= | P17: ='PROJECT DETAILS'!J55 -> 4 | Q17: m | U17: W= | V17: ='PROJECT DETAILS'!N55 -> 4 | W17: m
C18: Height from N.G.L to TB(top) | D18: ='PROJECT DETAILS'!B58 -> 1.3 | E18: m | I18: Height from N.G.L to TB(top) | J18: ='PROJECT DETAILS'!F58 -> 1.3 | K18: m | O18: Height from N.G.L to TB(top) | P18: ='PROJECT DETAILS'!J58 -> 0.6 | Q18: m | U18: Height from N.G.L to TB(top) | V18: ='PROJECT DETAILS'!N58 -> 0.6 | W18: m
C19: NO. OF PCS = | D19: ='PROJECT DETAILS'!B57 -> 2 | E19: PCS | I19: NO. OF PCS = | J19: ='PROJECT DETAILS'!F57 -> 4 | K19: PCS | O19: NO. OF PCS = | P19: ='PROJECT DETAILS'!J57 -> 5 | Q19: PCS | U19: NO. OF PCS = | V19: ='PROJECT DETAILS'!N57 -> 5 | W19: PCS
C20: V= | D20: =D18*D17*D16*D19 -> 41.6 | E20: cu.m. | I20: V= | J20: =J18*J17*J16*J19 -> 78 | K20: cu.m. | O20: V= | P20: =P18*P17*P16*P19 -> 616.8 | Q20: cu.m. | U20: V= | V20: =V18*V17*V16*V19 -> 616.8 | W20: cu.m.
C22: SP = Hsp x Wsp x Lsp
B23: SP = | C23: =D25*D26*D27 -> 8.60625 | D23: cu.m.
C25: Hsp = | D25: ='PROJECT DETAILS'!B133 -> 1.7 | E25: m
C26: Wsp+.25 = | D26: ='PROJECT DETAILS'!B134+0.25 -> 1.35 | E26: m
C27: Lsp+.25 = | D27: ='PROJECT DETAILS'!B135+0.25 -> 3.75 | E27: m
A29: CB1 | G29: CB2 | M29: CB3
C30: CB = Hcb x Wcb x Lcb | I30: CB = Hcb x Wcb x Lcb | O30: CB = Hcb x Wcb x Lcb
B31: CB = | C31: =D33*D34*D35 -> 0.4335 | D31: cu.m. | H31: CB = | I31: =J33*J34*J35 -> 0.4335 | J31: cu.m. | N31: CB = | O31: =P33*P34*P35 -> 0.4335 | P31: cu.m.
C33: Hcb= | D33: ='PROJECT DETAILS'!B141 -> 0.6 | E33: m | I33: Hcb= | J33: ='PROJECT DETAILS'!F141 -> 0.6 | K33: m | O33: Hcb= | P33: ='PROJECT DETAILS'!J141 -> 0.6 | Q33: m
C34: Wcb+.25 = | D34: ='PROJECT DETAILS'!B142+0.25 -> 0.85 | E34: m | I34: Wcb+.25 = | J34: ='PROJECT DETAILS'!F142+0.25 -> 0.85 | K34: m | O34: Wcb+.25 = | P34: ='PROJECT DETAILS'!J142+0.25 -> 0.85 | Q34: m
C35: Lcb+.25 = | D35: ='PROJECT DETAILS'!B143+0.25 -> 0.85 | E35: m | I35: Lcb+.25 = | J35: ='PROJECT DETAILS'!F143+0.25 -> 0.85 | K35: m | O35: Lcb+.25 = | P35: ='PROJECT DETAILS'!J143+0.25 -> 0.85 | Q35: m
A37: EMBANKMENT
A39: Ve = Vse - Vcb - Voe + Veb
A40: Ve = | B40: =B6-C43-C65+C86 -> 1308.8595 | C40: CU.M.
B42: Vcb = CFb + Ocb + Mb
B43: Vcb = | C43: =D45+D55+D57 -> 169.7365 | D43: cu.m.
C45: CFb = | D45: =SUM(C53,F53,K53,N53,S53,V53,AA53,AD53) -> 166.345 | E45: cu.m.
A46: CFb
A47: C1 | E47: F1 | I47: C2 | M47: F2 | Q47: C3 | U47: F3 | Y47: C4 | AC47: F4
B49: L = | C49: ='PROJECT DETAILS'!B11 -> 0.7 | D49: m | E49: L = | F49: ='PROJECT DETAILS'!B35 -> 3 | G49: m | J49: L = | K49: ='PROJECT DETAILS'!F11 -> 0.6 | L49: m | M49: L = | N49: ='PROJECT DETAILS'!F35 -> 2 | O49: m | R49: L = | S49: ='PROJECT DETAILS'!J11 -> 0.35 | T49: m | U49: L = | V49: ='PROJECT DETAILS'!J35 -> 1 | W49: m | Z49: L = | AA49: ='PROJECT DETAILS'!N11 -> 0.35 | AB49: m | AC49: L = | AD49: ='PROJECT DETAILS'!N35 -> 1 | AE49: m
B50: W = | C50: ='PROJECT DETAILS'!B12 -> 1.1 | D50: m | E50: W = | F50: ='PROJECT DETAILS'!B36 -> 3 | G50: m | J50: W = | K50: ='PROJECT DETAILS'!F12 -> 0.6 | L50: m | M50: W = | N50: ='PROJECT DETAILS'!F36 -> 2 | O50: m | R50: W = | S50: ='PROJECT DETAILS'!J12 -> 0.35 | T50: m | U50: W = | V50: ='PROJECT DETAILS'!J36 -> 1 | W50: m | Z50: W = | AA50: ='PROJECT DETAILS'!N12 -> 0.35 | AB50: m | AC50: W = | AD50: ='PROJECT DETAILS'!N36 -> 1 | AE50: m
B51: Hb = | C51: ='PROJECT DETAILS'!B10 -> 2.5 | D51: m | E51: T = | F51: ='PROJECT DETAILS'!B37 -> 0.8 | G51: m | J51: Hb = | K51: ='PROJECT DETAILS'!F10 -> 2 | L51: m | M51: T = | N51: ='PROJECT DETAILS'!F37 -> 0.6 | O51: m | R51: Hb = | S51: ='PROJECT DETAILS'!J10 -> 0.55 | T51: m | U51: T = | V51: ='PROJECT DETAILS'!J37 -> 0.25 | W51: m | Z51: Hb = | AA51: ='PROJECT DETAILS'!N10 -> 0.55 | AB51: m | AC51: T = | AD51: ='PROJECT DETAILS'!N37 -> 0.25 | AE51: m
B52: NO. OF PCS = | C52: =C12 -> 10 | D52: pcs | E52: NO. OF PCS = | F52: =C52 -> 10 | G52: pcs | J52: NO. OF PCS = | K52: =H12 -> 20 | L52: pcs | M52: NO. OF PCS = | N52: =K52 -> 20 | O52: pcs | R52: NO. OF PCS = | S52: =M12 -> 20 | T52: pcs | U52: NO. OF PCS = | V52: =S52 -> 20 | W52: pcs | Z52: NO. OF PCS = | AA52: =R12 -> 20 | AB52: pcs | AC52: NO. OF PCS = | AD52: =AA52 -> 20 | AE52: pcs
C53: =C52*C51*C50*C49 -> 19.25 | F53: =F52*F51*F50*F49 -> 72 | K53: =K52*K51*K50*K49 -> 14.4 | N53: =N52*N51*N50*N49 -> 48 | S53: =S52*S51*S50*S49 -> 1.3475 | V53: =V52*V51*V50*V49 -> 5 | AA53: =AA52*AA51*AA50*AA49 -> 1.3475 | AD53: =AD52*AD51*AD50*AD49 -> 5
...

Sheet SUMMARIZE QUANTITY
A1: SCOPE OF WORK | B1: QUANTITY | C1: UNITS
A3: STRUCTURAL EXCAVATION | B3: =ESTIMATES!B6 -> 2038.388 | C3: cu.m.
A4: EMBANKMENT | B4: =ESTIMATES!B40 -> 1308.8595 | C4: cu.m.
A5: MASONRY WORKS | B5: =ESTIMATES!C245 -> 130.7675 | C5: sq.m.
A6: STRUCTURAL CONCRETE | B6: =ESTIMATES!B103 -> 1704.783 | C6: cu.m.
A7: REINFORCE STEEL BAR | B7: =ESTIMATES!B107 -> 91.184 | C7: kgs
A8: STEEL WORKS | B8: =SUM(B10:B27,E10:E27) -> 243.33 | C8: ln.m.
A9: TOP BARS | D9: TOP BARS
A10: GIRT 1 | B10: =ESTIMATES!B265 -> 1 | C10: ln.m. | D10: GIRT 1 | E10: =ESTIMATES!I265 -> 0 | F10: ln.m.
A11: GIRT 2 | B11: =ESTIMATES!B266 -> 1 | C11: ln.m. | D11: GIRT 2 | E11: =ESTIMATES!I266 -> 0 | F11: ln.m.
A12: GIRT 3 | B12: =ESTIMATES!B267 -> 2 | C12: ln.m. | D12: GIRT 3 | E12: =ESTIMATES!I267 -> 0 | F12: ln.m.
A13: GIRT 4 | B13: =ESTIMATES!B268 -> 3 | C13: ln.m. | D13: GIRT 4 | E13: =ESTIMATES!I268 -> 0 | F13: ln.m.
A14: GIRT 5 | B14: =ESTIMATES!B269 -> 4 | C14: ln.m. | D14: GIRT 5 | E14: =ESTIMATES!I269 -> 0 | F14: ln.m.
A15: GIRT 6 | B15: =ESTIMATES!B270 -> 5 | C15: ln.m. | D15: GIRT 6 | E15: =ESTIMATES!I270 -> 0 | F15: ln.m.
A16: GIRT 7 | B16: =ESTIMATES!B271 -> 6 | C16: ln.m. | D16: GIRT 7 | E16: =ESTIMATES!I271 -> 0 | F16: ln.m.
A17: GIRT 8 | B17: =ESTIMATES!B272 -> 7 | C17: ln.m. | D17: GIRT 8 | E17: =ESTIMATES!I272 -> 0 | F17: ln.m.
A18: GIRT 9 | B18: =ESTIMATES!B273 -> 8 | C18: ln.m. | D18: GIRT 9 | E18: =ESTIMATES!I273 -> 0 | F18: ln.m.
A19: TRUSS 1 | B19: =ESTIMATES!E265 -> 53.44 | C19: ln.m. | D19: TRUSS 1 | E19: =ESTIMATES!L265 -> 45 | F19: ln.m.
A20: TRUSS 2 | B20: =ESTIMATES!E266 -> 53.44 | C20: ln.m. | D20: TRUSS 2 | E20: =ESTIMATES!L266 -> 21.95 | F20: ln.m.
A21: TRUSS 3 | B21: =ESTIMATES!E267 -> 25.4 | C21: ln.m. | D21: TRUSS 3 | E21: =ESTIMATES!L267 -> 7.1 | F21: ln.m.
A22: TRUSS 4 | B22: =ESTIMATES!E268 -> 0 | C22: ln.m. | D22: TRUSS 4 | E22: =ESTIMATES!L268 -> 0 | F22: ln.m.
A23: TRUSS 5 | B23: =ESTIMATES!E269 -> 0 | C23: ln.m. | D23: TRUSS 5 | E23: =ESTIMATES!L269 -> 0 | F23: ln.m.
A24: TRUSS 6 | B24: =ESTIMATES!E270 -> 0 | C24: ln.m. | D24: TRUSS 6 | E24: =ESTIMATES!L270 -> 0 | F24: ln.m.
A25: TRUSS 7 | B25: =ESTIMATES!E271 -> 0 | C25: ln.m. | D25: TRUSS 7 | E25: =ESTIMATES!L271 -> 0 | F25: ln.m.
A26: TRUSS 8 | B26: =ESTIMATES!E272 -> 0 | C26: ln.m. | D26: TRUSS 8 | E26: =ESTIMATES!L272 -> 0 | F26: ln.m.
A27: TRUSS 9 | B27: =ESTIMATES!E273 -> 0 | C27: ln.m. | D27: TRUSS 9 | E27: =ESTIMATES!L273 -> 0 | F27: ln.m.
A28: ROOFING WORKS | B28: =ESTIMATES!C254 -> 127.4 | C28: sq.m.
A29: PAINTING WORKS | B29: =ESTIMATES!B283 -> 388.935 | C29: sq.m.
A30: TILE WORKS | B30: =ESTIMATES!B279 -> 89.8 | C30: sq.m.
A31: SEPTIC VAULT | B31: ='PROJECT DETAILS'!B222 -> 1 | C31: lot
A32: PLUMBING WORKS | B32: ='PROJECT DETAILS'!B221 -> 1 | C32: lot
A33: ELETRICAL WORKS | B33: ='PROJECT DETAILS'!B220 -> 1 | C33: circuit
A34: FORMWORKS | B34: ='PROJECT DETAILS'!B226 -> 1 | C34: lumpsum
A35: CARPENTRY WORKS | B35: =ESTIMATES!C260 -> 127.4 | C35: sq.m.
A36: DOORS AND WINDOWS | B36: ='PROJECT DETAILS'!B227 -> 17 | C36: units
A37: BILLBOARDS | B37: ='PROJECT DETAILS'!B224 -> 1 | C37: lumpsum
A38: MOBILIZATION/DEMOLIZATION | B38: ='PROJECT DETAILS'!B228 -> 10 | C38: days
A39: SAFETY PROGRAM | B39: ='PROJECT DETAILS'!B223 -> 1 | C39: lumpsum
A40: BUNKHOUSE | B40: ='PROJECT DETAILS'!B225 -> 1 | C40: lot
A41: DEMOLITON | B41: ='PROJECT DETAILS'!B214 -> 123 | C41: sq.m.

Sheet materials
A1: Scope of Works | B1: Item Discription | C1: Unit | D1: hour rate | E1: CANVASS OF CONSTRUCTION MATERIALS
E2: HAPPY LIVING | F2: CSC | G2: CHUI KIM Int. | H2: CITI HARWARE | I2: HOME SOLUTION | J2: SPRINTER | K2: BUILT-N | L2: DYNAMIC | M2: ADOPTED PRICE
A3: STRUCTURAL EXCAVATION | C3: sq.m.
B5: EQUIPMENTS
B6: BACKHOE | D6: 1537
B7: DUMPTRUCK | D7: 676
A9: EMBANKMENT | C9: sq.m.
B11: EQUIPMENTS
B12: MOTORIZED ROAD GRADER | D12: 2173
B13: WATER TRUCK | D13: 1065
B14: VIBRATORY ROLLER | D14: 1507
B15: Backfill | C15: cu.m | J15: 450 | K15: 500 | L15: 500
B16: Common Borrow (W/ 25% Shringkage factor) | C16: cu.m. | M16: 400 | X16: =T16*Q16 -> 0
B17: Embankment (Heavy Mix) | C17: cu.m | J17: 450 | K17: 400 | L17: 400
A18: STRUCTURAL CONCRETE | C18: sq.m.
B20: Cement, Portland | C20: bags | F20: 320 | J20: 305 | K20: 290 | L20: 290
B21: Cement Sahara | C21: pcks | J21: 45 | K21: 50 | L21: 50
B22: Cement, Wallright | C22: bags | J22: 295 | K22: 287 | L22: 285
B23: Cement, Wallright | C23: bags | J23: 295 | K23: 287 | L23: 285
B24: Gravel, Passing 3/4"ɸ (round) | C24: cu.m | E24: 1010 | F24: 4000 | J24: 1150 | K24: 1200 | L24: 1200
B25: Gravel, Passing 3/4"ɸ (crash) | C25: cu.m | E25: 1055
B26: Gravel, Passing 1"ɸ (round) | C26: cu.m | E26: 795 | F26: 4000 | J26: 1200
B27: Gravel, Passing 1"ɸ (crash) | C27: cu.m | E27: 900
B28: Gravel, Passing 2"ɸ (round) | C28: cu.m | E28: 655 | F28: 4800 | J28: 1200
B29: Gravel, Passing 2"ɸ (crash) | C29: cu.m | E29: 655
B30: W. Sand | C30: cu.m | E30: 325 | F30: 1500 | J30: 450 | K30: 500 | L30: 500
B31: Screened Sand | C31: cu.m | F31: 3500 | J31: 500 | K31: 420
A33: REINFORCE STEEL BAR | C33: sq.m.
B35: Cutting Disc 4"ɸ, Steel | C35: pcs | J35: 95 | K35: 125 | L35: 600
B36: Def. Bar 25mmф | C36: length | F36: 1100 | J36: 990
B37: Def. Bar 20mmф | C37: length | F37: 650 | J37: 580
B38: Def. Bars, 10mmф | C38: length | F38: 150 | J38: 160 | K38: 155 | L38: 175
B39: Def. Bars, 12mmɸ | C39: length | F39: 200 | J39: 250 | K39: 250 | L39: 280
B40: Def. Bars, 16mmф | C40: length | F40: 380 | J40: 380 | K40: 410 | L40: 470
B41: Def. Bar 6mmф | C41: length | J41: 95 | L41: 80
B42: Def. Bars, 8mmф | C42: length | J42: 120 | K42: 120 | L42: 135
B43: Def. Bar, 9mmф | C43: length | J43: 135 | K43: 140 | L43: 165
B44: Hacksaw Blade | C44: pcs | J44: 80 | K44: 90 | L44: 90
B45: W. Sand | C45: cu.m | E45: 325 | F45: 1500 | J45: 450 | K45: 500 | L45: 500
B46: Screened Sand | C46: cu.m | F46: 3500 | J46: 500 | K46: 420
...

Sheet OBR 
A1: Republic of the Philippines
A2: Province of South Cotabato
A3: City of Koronadal
A5: OBLIGATION REQUEST | E5: No. | F5: 100-2018-02
A6: Payee/Office
A7: Office: | B7: CEO | E7: Date:
A8: Address: | B8: City of Koronadal, South Cotabato
A9: Responsibilty | B9: Particulars | C9: F.P.P | D9: Account | E9: Amount
A10: Center | D10: Code
B11: Capital Outlay | D11: 300
B13: Local Development FUND | C13: 8919
B16: Other Structure | D16: 107-02-010
B17: ='POW COVER'!X9 -> Construction of Covered Pathway at City hall Entrance/Exit
B18: ='POW COVER'!E10 -> ( 29 SPAN, 3m length/span)
B19: Materials | F19: =BOM!G191 -> 141931
B20: Labor | F20: =BOM!G243 -> 541064.48
B21: Equipment Rental | F21: =BOM!G244 -> 21350
A24: Total | F24: =SUM(F19:F23) -> 704345.48
A25: Certified: | B25: Charges to appropriate/allotment
B26: necessary, lawful and under my direct supervision
D27: Existence of available appropriation
B28: Supporting Documents valid, proper and legal
A31: Signature: | D31: Signature:
A32: Printed Name: | B32: PETER B. MIGUEL, M.D.,FPSO-HNS | D32: Printed Name: | E32: JULIETA R. GASTALA, MPA
A33: Position: | B33: City Mayor | D33: Position: | E33: City Budget Officer
A35: Date: | D35: Date:
A48: Republic of the Philippines
A49: Province of South Cotabato
A50: City of Koronadal
A51: OBLIGATION REQUEST | E51: No. | F51: 100-2013-11-
A52: Payee/Office
A53: Office: | B53: CMO - SEF | E53: Date:
A54: Address: | B54: City of Koronadal, South Cotabato
A55: Responsibilty | B55: Particulars | C55: F.P.P | D55: Account | E55: Amount
A56: Center | D56: Code
B57: Capital Outlay | D57: 300
B59: Public Education | C59: 3321
B62: Other Structure | D62: 215
B63: Materials | F63: =+'[1]POW SEF'!F187 -> 19500
B64: Labor | F64: =+'[1]POW SEF'!F188+'[1]POW SEF'!F191 -> 15100
...

Sheet BACKUP

Sheet BOM
A1: Republic of the Philippines
A2: Province of South Cotabato
A3: City of Koronadal
A4: OFFICE OF THE CITY ENGINEER | I4: 9
A5: Project: | B5: Proposed Covered Pathway at PRE Fabrication Isolation Facility
A6: Location: | B6: Back of New City Hall Building, Barangay Zone -111 Koronadal City
A7: Project Cost Php: | B7: =G245 -> 9764780 | H7: 1.1
A9: PROGRAM OF WORKS
A11: ITEM | B11: SCOPE OF WORKS
A13: SPL - 1 | B13: PRE FABRICATION FACILITY | C13: QUANTITY = | D13: 1 | E13: lumpsum
B14: 6m length x 3m width x 2.8m height
C18: a. sliding windows with PVC ( 1150mm x 1130mm) - 2 sets | D18: 18 | E18: lot | F18: 444444.44 | G18: =D18*F18 -> 8000000
C20: b. High Quality steel door 725mmx1970mm ( door panel 0.4mm thick, frame 1.0mm) - 2 sets
C22: c. Flooring 18mm MGO board with quality PVC Cover
C24: d. Wall 50mm polystyrene insulation
C25: e. 50mm glass wool with interior with interior ceilings
C27: f. 4mm powder coated Galvanized sheet roof cover
C28: g. Electrical ( 2 switch, 4 - 2gang, 2 electrical distribution box, 2 led light 18 wats, 2 led light 12 watts, 2 breaker, embedded electrical wiring )
C31: h. 2 -Table and 2 - Chairs for nurse station
C32: i. television - 2 sets
C33: j. steel bed- 2 sets (except for nurse station)
C34: k. foam 3 in 2- sets (except for nurse station)
C35: l. pillowcase - 2 sets (except for nurse station)
C36: m. bedsheet blanket - 4 sets (except for nurse station)
... C44: u. Installation of pre fabrication facility
F45: SUB TOTAL = | G45: =G18 -> 8000000
F47: DIRECT COST= | G47: =G45 -> 8000000
F48: UNIT COST = | G48: =G47/D18 -> 444444.44
A50: ='[2]DUPA KCES1'!F446 -> SPL-5 | B50: FORMWORKS | C50: QUANTITY = | D50: 1 | E50: lumpsum | I50: per span quantity | J50: =D50/17 -> 0.058823529 | K50: =J50*28 -> 1.6470588
A52: Materials
D53: QUANTITY | E53: UNITS | F53: UNIT COST | G53: AMOUNT
C55: 100 coco-lumber ( 2x3x12 ) | D55: 500 | E55: bd.ft | F55: 32.2 | G55: =D55*F55 -> 16100
C56: 100 coco lumber (2x2x12) | D56: 300 | E56: bd.ft | F56: 32.2 | G56: =D56*F56 -> 9660
C57: Marine plywood | D57: 8 | E57: sht | F57: 900 | G57: =D57*F57 -> 7200
C58: Leveling Hose | D58: 20 | E58: m | F58: 35 | G58: =D58*F58 -> 700
C59: Nylon string | D59: 15 | E59: roll | F59: 35 | G59: =D59*F59 -> 525
C60: CWN 4" | D60: 15 | E60: kgs | F60: 85 | G60: =D60*F60 -> 1275
C61: CWN 2 1/2" | D61: 15 | E61: kgs | F61: 85 | G61: =D61*F61 -> 1275
C62: CWN 1 1/2" | D62: 5 | E62: kgs | F62: 85 | G62: =D62*F62 -> 425
F63: SUB TOTAL = | G63: =SUM(G55:G62) -> 37160
...

Sheet SUMARRY
D1: Republic of the Philippines
D2: Province of South Cotabato
D3: City of Koronadal
D4: CITY MAYORS OFFICE - BARANGAY DEVELOPMENT PROGRAM
D5: PROGRAM OF WORK/BUDGET COST FOR KORONADAL CITY INFRASTRUCTURE PROJECTS
D7: PROJECT: | G7: COMPLETION, RENOVATION AND IMPROVEMENT OF DAY CARE CENTER
N8: Date:
D9: Location: | G9: SITIO BADAC, BARANGAY SARAVIA, PUROK SAN FRANCISCO BARANGAY NEW PANGASINAN, | N9: Total No.of Units: | Q9: 18900000
G10: PUROK BAGONG LIPUNAN BARANGAY SAN ISIDRO AND PUROK KAUSWAGAN BARANGAY SARAVIA | N10: Classification: | Q10: =O136 -> #REF!
N11: Starting Date: | O11: Upon Approval
N12: Total Project Duration: | O12: 70 CD
D13: Estimated Project Cost: | G13: =O136 -> #REF! | N13: No. of Working Days:
D14: Source of Fund: | G14: 20 % LOCAL DEVELOPMENT PLAN ( AIP 2025 ) | N14: No. of Pre-determined:
D15: Project limits: | N15: Unworkable Days:
A17: ITEM | B17: DEPENDENCY | C17: CD | D17: ITEM NO. | F17: DESCRIPTION OF WORK | K17: % OF | L17: EQUIPMENT
K18: TOTAL | L18: QTY | N18: DESCRIPTION
A19: 1 | C19: 11 | D19: =D75 -> RENOVATION OF DAY CARE CENTER AT SITIO BADAC BARANGAY SARAVIA | L19: 3 | N19: ONE BAGGER MIXER
A20: 1 | C20: 11 | D20: =D76 -> I | F20: =F76 -> STRUCTURAL CONCRETE | K20: =O76/O$128 -> #REF! | L20: 5 | N20: BAR CUTTER
A21: 1 | C21: 11 | D21: =D77 -> II | F21: =F77 -> REINFORCE STEEL BAR | K21: =O77/O$128 -> #REF! | L21: 5 | N21: BAR BENDER
A22: 1 | C22: 11 | D22: =D78 -> III | F22: =F78 -> FORMWORKS | K22: =O78/O$128 -> #REF!
A23: 1 | C23: 11 | D23: =D79 -> IV | F23: =F79 -> MASONRY WORKS ( CHB Laying and Plastering ) | K23: =O79/O$128 -> #REF!
A24: 1 | C24: 11 | D24: =D80 -> V | F24: =F80 -> ROOFING WORKS | K24: =O80/O$128 -> #REF!
A25: 1 | C25: 11 | D25: =D81 -> VI | F25: =F81 -> PAINTING WORKS | K25: =O81/O$128 -> #REF!
A26: 1 | C26: 11 | D26: =D82 -> VII | F26: =F82 -> PLUMBING AND TILE WORKS | K26: =O82/O$128 -> #REF!
A27: 1 | C27: 11 | D27: =D83 -> VIII | F27: =F83 -> DOORS AND WINDOWS | K27: =O83/O$128 -> #REF!
A28: 1 | C28: 11 | D28: =D84 -> IX | F28: =F84 -> ELECTRICAL WORKS | K28: =O84/O$128 -> #REF!
A29: 1 | C29: 11 | D29: =D85 -> X | F29: =F85 -> BILLBOARD | K29: =O85/O$128 -> #REF!
A30: 1 | C30: 11 | D30: =D86 -> XI | F30: =F86 -> CEILING WORKS | K30: =O86/O$128 -> #REF!
A31: 1 | C31: 11 | D31: =D87 -> XII | F31: =F87 -> STEEL WORKS | K31: =O87/O$128 -> #REF!
A32: 1 | C32: 11 | D32: =D88 -> SUB TOTAL: | K32: =SUM(K20:K31) -> #REF!
A33: 1 | C33: 11 | D33: =D89 -> IMPROVEMENT OF DAY CARE CENTER AT PUROK SAN FRANCISCO BARANGAY SITE BARANGAY NEW PANGASINAN
A34: 1 | C34: 11 | D34: =D90 -> I | F34: =F90 -> STRUCTURAL CONCRETE | K34: =O90/O$128 -> #REF!
A35: 1 | C35: 11 | D35: =D91 -> II | F35: =F91 -> REINFORCE STEEL BAR | K35: =O91/O$128 -> #REF!
A36: 1 | C36: 11 | D36: =D92 -> III | F36: =F92 -> FORMWORKS | K36: =O92/O$128 -> #REF!
A37: 1 | C37: 11 | D37: =D93 -> IV | F37: =F93 -> MASONRY WORKS ( CHB Laying and Plastering ) | K37: =O93/O$128 -> #REF!
A38: 1 | C38: 11 | D38: =D94 -> V | F38: =F94 -> ROOFING WORKS | K38: =O94/O$128 -> #REF!
A39: 1 | C39: 11 | D39: =D95 -> VI | F39: =F95 -> PAINTING WORKS | K39: =O95/O$128 -> #REF!
A40: 1 | C40: 11 | D40: =D96 -> VII | F40: =F96 -> PLUMBING AND TILE WORKS | K40: =O96/O$128 -> #REF!
A41: 1 | C41: 11 | D41: =D97 -> VIII | F41: =F97 -> DOORS AND WINDOWS | K41: =O97/O$128 -> #REF!
A42: 1 | C42: 11 | D42: =D98 -> IX | F42: =F98 -> ELECTRICAL WORKS | K42: =O98/O$128 -> #REF!
...

Sheet PR
A2: Name of the Procuring Entity | E2: Project Reference Number:
E3: Name of Project:
E4: =SUMARRY!G7 -> COMPLETION, RENOVATION AND IMPROVEMENT OF DAY CARE CENTER
A6: Standard Form Number: SF-GOOD-59 | E6: Location of Project:
A7: Revised on July 04, 2022 | E7: =SUMARRY!G9 -> SITIO BADAC, BARANGAY SARAVIA, PUROK SAN FRANCISCO BARANGAY NEW PANGASINAN,
A8: Standard Form Title: Purchase Request
E9: =SUMARRY!G10 -> PUROK BAGONG LIPUNAN BARANGAY SAN ISIDRO AND PUROK KAUSWAGAN BARANGAY SARAVIA
A13: PURCHASE REQUEST
A14: CITY GOVERNMENT OF KORONADAL
A15: LGU
A16: Department: | C16: CMO-BDP | E16: PR No.: | F16: Date: February 24,2025
A17: Section: | E17: SAI No.:
A18: Stock | B18: Unit | C18: Item Description | E18: QTY. | F18: Unit Cost | G18: Amount
A19: No.
A20: =BADAC!B6 -> RENOVATION OF DAY CARE CENTER AT SITIO BADAC BARANGAY SARAVIA
A21: 1 | B21: =BADAC!E27 -> bags | C21: =BADAC!C27 -> Premium Portland Cement ASTM C595 | E21: =BADAC!D27 -> 24 | F21: =BADAC!F27 -> 310 | G21: =F21*E21 -> 7440
A22: =A21+1 -> 2 | B22: =BADAC!E28 -> cu.m. | C22: =BADAC!C28 -> W. Sand | E22: =BADAC!D28 -> 10 | F22: =BADAC!F28 -> 600 | G22: =F22*E22 -> 6000
A23: =A22+1 -> 3 | B23: =BADAC!E29 -> cu.m. | C23: =BADAC!C29 -> Gravel 3/4", Crushed | E23: =BADAC!D29 -> 5 | F23: =BADAC!F29 -> 1450 | G23: =F23*E23 -> 7250 | H23: =SUM(G21:G23) -> 20690
A24: =A23+1 -> 4 | B24: =BADAC!E46 -> length | C24: =BADAC!C46 -> 10mm diam x 6m corr. Deform bar | E24: =BADAC!D46 -> 20 | F24: =BADAC!F46 -> 210 | G24: =F24*E24 -> 4200
A25: =A24+1 -> 5 | B25: =BADAC!E47 -> length | C25: =BADAC!C47 -> 12mm diam x 6m corr. Deform bar | E25: =BADAC!D47 -> 12 | F25: =BADAC!F47 -> 310 | G25: =F25*E25 -> 3720
A26: =A25+1 -> 6 | B26: =BADAC!E48 -> kgs | C26: =BADAC!C48 -> Tie Wire # 16 | E26: =BADAC!D48 -> 10 | F26: =BADAC!F48 -> 110 | G26: =F26*E26 -> 1100
A27: =A26+1 -> 7 | B27: =BADAC!E49 -> pcs | C27: =BADAC!C49 -> Cutting Disc 4" ( Flexiarapid super A 60 U ) | E27: =BADAC!D49 -> 5 | F27: =BADAC!F49 -> 210 | G27: =F27*E27 -> 1050 | H27: =SUM(G24:G27) -> 10070
A28: =A27+1 -> 8 | B28: =BADAC!E67 -> bd.ft | C28: =BADAC!C67 -> Coco-lumber ( 2"x3"x12' ) | E28: =BADAC!D67 -> 120 | F28: =BADAC!F67 -> 38 | G28: =F28*E28 -> 4560
A29: =A28+1 -> 9 | B29: =BADAC!E68 -> bd.ft | C29: =BADAC!C68 -> Coco-lumber ( 2"x2"x12' ) | E29: =BADAC!D68 -> 80 | F29: =BADAC!F68 -> 38 | G29: =F29*E29 -> 3040
A30: =A29+1 -> 10 | B30: =BADAC!E69 -> sht | C30: =BADAC!C69 -> Ordinary plywood 10MM 4'X8' | E30: =BADAC!D69 -> 4 | F30: =BADAC!F69 -> 714 | G30: =F30*E30 -> 2856
A31: =A30+1 -> 11 | B31: =BADAC!E70 -> roll | C31: =BADAC!C70 -> Nylon string ( 0.40mm ) | E31: =BADAC!D70 -> 4 | F31: =BADAC!F70 -> 68 | G31: =F31*E31 -> 272
A32: =A31+1 -> 12 | B32: =BADAC!E71 -> kgs | C32: =BADAC!C71 -> CWN 4" | E32: =BADAC!D71 -> 5 | F32: =BADAC!F71 -> 94 | G32: =F32*E32 -> 470
A33: =A32+1 -> 13 | B33: =BADAC!E72 -> kgs | C33: =BADAC!C72 -> CWN 3" | E33: =BADAC!D72 -> 5 | F33: =BADAC!F72 -> 94 | G33: =F33*E33 -> 470
A34: =A33+1 -> 14 | B34: =BADAC!E73 -> kgs | C34: =BADAC!C73 -> Tie Wire # 16 | E34: =BADAC!D73 -> 3.1182 | F34: =BADAC!F73 -> 110 | G34: =F34*E34 -> 343.002
A35: =A34+1 -> 15 | B35: =BADAC!E74 -> kgs | C35: =BADAC!C74 -> CWN 1 1/2" | E35: =BADAC!D74 -> 3 | F35: =BADAC!F74 -> 94 | G35: =F35*E35 -> 282
A36: =A35+1 -> 16 | B36: =BADAC!E75 -> m | C36: =BADAC!C75 -> Hardware cloth 1/8" | E36: =BADAC!D75 -> 3 | F36: =BADAC!F75 -> 189 | G36: =F36*E36 -> 567 | H36: =SUM(G28:G36) -> 12860.002
A37: =A36+1 -> 17 | B37: =BADAC!E93 -> pcs | C37: =BADAC!C93 -> CHB 4"x8"x16" | E37: =BADAC!D93 -> 300 | F37: =BADAC!F93 -> 13 | G37: =F37*E37 -> 3900
A38: =A37+1 -> 18 | B38: =BADAC!E94 -> length | C38: =BADAC!C94 -> 10mm diam x 6m corr. Deform bar | E38: =BADAC!D94 -> 20 | F38: =BADAC!F94 -> 210 | G38: =F38*E38 -> 4200
A39: =A38+1 -> 19 | B39: =BADAC!E95 -> bags | C39: =BADAC!C95 -> Premium Portland Cement ASTM C595 | E39: =BADAC!D95 -> 90 | F39: =BADAC!F95 -> 310 | G39: =F39*E39 -> 27900
A40: =A39+1 -> 20 | B40: =BADAC!E96 -> cu.m. | C40: =BADAC!C96 -> W. Sand | E40: =BADAC!D96 -> 1 | F40: =BADAC!F96 -> 600 | G40: =F40*E40 -> 600 | H40: =SUM(G37:G40) -> 36600
A41: =A40+1 -> 21 | B41: =BADAC!E114 -> sq.m. | C41: =BADAC!C114 -> Pre fabricated Long Span (0.40mm THK) | E41: =BADAC!D114 -> 18 | F41: =BADAC!F114 -> 520 | G41: =F41*E41 -> 9360
A42: =A41+1 -> 22 | B42: =BADAC!E115 -> pcs | C42: =BADAC!C115 -> Tek Screw #2 | E42: =BADAC!D115 -> 200 | F42: =BADAC!F115 -> 3 | G42: =F42*E42 -> 600
A43: =A42+1 -> 23 | B43: =BADAC!E116 -> length | C43: =BADAC!C116 -> Cee-Purlins 1.2mmx2"x4"x6m | E43: =BADAC!D116 -> 7 | F43: =BADAC!F116 -> 650 | G43: =F43*E43 -> 4550
A44: =A43+1 -> 24 | B44: =BADAC!E117 -> length | C44: =BADAC!C117 -> Cee Purlins 1.2mmx2"x3"x6m | E44: =BADAC!D117 -> 12 | F44: =BADAC!F117 -> 550 | G44: =F44*E44 -> 6600
A45: =A44+1 -> 25 | B45: =BADAC!E118 -> pcs | C45: =BADAC!C118 -> Grinding Stone 4" | E45: =BADAC!D118 -> 5 | F45: =BADAC!F118 -> 120 | G45: =F45*E45 -> 600
...

Sheet BADAC
A1: Republic of the Philippines
A2: Province of South Cotabato | H2: =J270 -> 0.44738746
A3: City of Koronadal | H3: =H352 -> -0.002
A4: CITY MAYORS OFFICE - BARANGAY DEVELOPMENT PROGRAM
A6: Project: | B6: RENOVATION OF DAY CARE CENTER AT SITIO BADAC BARANGAY SARAVIA
A7: Location:
A8: Project Cost Php: | B8: 400000
A10: PROGRAM OF WORKS
A12: ITEM | B12: SCOPE OF WORKS
A15: I | B15: STRUCTURAL CONCRETE | C15: QUANTITY = | D15: =N16+N18+N20 -> 2.444 | E15: cu.m. | H15: 0.4 | J15: L | K15: W | L15: T | N15: VOLUME
H16: 0.4 | J16: 0.6 | K16: 0.6 | L16: 0.1 | M16: 4 | N16: =J16*K16*L16*M16 -> 0.144
A17: Labor | J17: L | K17: W | L17: T | N17: VOLUME
D18: NO. OF PERSONS | E18: NO. OF HOURS | F18: RATE PER HOUR | G18: AMOUNT | J18: 0.25 | K18: 0.25 | L18: 2 | M18: 4 | N18: =J18*K18*L18*M18 -> 0.5
C19: Construction Foreman | D19: 1 | E19: 6 | F19: 615 | G19: =F19*E19*D19 -> 3690 | J19: L | K19: W | L19: T | N19: VOLUME
C20: Skilled Worker ( Carpenter ) | D20: 1 | E20: =E19 -> 6 | F20: 414 | G20: =F20*E20*D20 -> 2484 | J20: 3 | K20: 6 | L20: 0.1 | M20: 1 | N20: =J20*K20*L20*M20 -> 1.8
C21: Skilled Worker ( Mason ) | D21: 2 | E21: =E20 -> 6 | F21: 390 | G21: =F21*E21*D21 -> 4680
C22: Laborer | D22: 2 | E22: =E21 -> 6 | F22: 341 | G22: =F22*E22*D22 -> 4092
F23: SUB TOTAL = | G23: =SUM(G19:G22) -> 14946 | H23: =G23/G32 -> 0.41940734
A24: Materials | H24: 1
D25: QUANTITY | E25: UNITS | F25: UNIT COST | G25: AMOUNT | H25: =#REF! -> #REF!
H26: =H15*H16*H24*H25 -> #REF!
C27: Premium Portland Cement ASTM C595 | D27: =ROUNDUP(D$15*9.5,0) -> 24 | E27: bags | F27: 310 | G27: =F27*D27 -> 7440
C28: W. Sand | D28: 10 | E28: cu.m. | F28: 600 | G28: =F28*D28 -> 6000
C29: Gravel 3/4", Crushed | D29: 5 | E29: cu.m. | F29: 1450 | G29: =F29*D29 -> 7250
F30: SUB TOTAL = | G30: =SUM(G27:G29) -> 20690
F32: DIRECT COST= | G32: =G30+G23 -> 35636
F33: UNIT COST = | G33: =G32/D15 -> 14581.015
A35: II | B35: REINFORCE STEEL BAR | C35: QUANTITY = | D35: =D46*0.616*6+D47*0.888*6 -> 137.856 | E35: kgs | H35: 0.4 | J35: VERT
H36: 0.4 | J36: l | K36: PCS | L36: LN.M.
A37: Labor | J37: 3 | K37: =110/0.4 -> 275 | L37: =J37*K37 -> 825
D38: NO. OF PERSONS | E38: NO. OF HOURS | F38: RATE PER HOUR | G38: AMOUNT
C39: Construction Foreman | D39: 1 | E39: 4 | F39: 615 | G39: =F39*E39*D39 -> 2460 | J39: HOR .BAR
C40: Skilled Worker ( Steel Man ) | D40: 1 | E40: =E39 -> 4 | F40: 390 | G40: =F40*E40*D40 -> 1560 | J40: 110 | K40: 10 | L40: =J40*K40 -> 1100
C41: Laborer | D41: 2 | E41: =E40 -> 4 | F41: 341 | G41: =F41*E41*D41 -> 2728
F42: SUB TOTAL = | G42: =SUM(G39:G41) -> 6748 | H42: =G42/G52 -> 0.40123677 | J42: PLANKS
A43: Materials | H43: 1 | J43: l | K43: PCS | L43: LN.M.
D44: QUANTITY | E44: UNITS | F44: UNIT COST | G44: AMOUNT | H44: =#REF! -> #REF! | J44: 4 | K44: 110 | L44: =J44*K44 -> 440
H45: =H35*H36*H43*H44 -> #REF!
C46: 10mm diam x 6m corr. Deform bar | D46: 20 | E46: length | F46: 210 | G46: =F46*D46 -> 4200
C47: 12mm diam x 6m corr. Deform bar | D47: 12 | E47: length | F47: 310 | G47: =F47*D47 -> 3720
...

Sheet SAN FRAN BO4
A1: Republic of the Philippines
A2: Province of South Cotabato | H2: =J268 -> 0.45156841
A3: City of Koronadal | H3: =H295 -> -0.003
A4: CITY MAYORS OFFICE - BARANGAY DEVELOPMENT PROGRAM
A6: Project: | B6: IMPROVEMENT OF DAY CARE CENTER AT PUROK SAN FRANCISCO BARANGAY SITE BARANGAY NEW PANGASINAN
A7: Location:
A8: Project Cost Php: | B8: 400000
A10: PROGRAM OF WORKS
A12: ITEM | B12: SCOPE OF WORKS
A15: I | B15: STRUCTURAL CONCRETE | C15: QUANTITY = | D15: =N16+N18+N20*5 -> 9.644 | E15: cu.m. | H15: 0.4 | J15: L | K15: W | L15: T | N15: VOLUME
H16: 0.4 | J16: 0.6 | K16: 0.6 | L16: 0.1 | M16: 4 | N16: =J16*K16*L16*M16 -> 0.144
A17: Labor | J17: L | K17: W | L17: T | N17: VOLUME
D18: NO. OF PERSONS | E18: NO. OF HOURS | F18: RATE PER HOUR | G18: AMOUNT | J18: 0.25 | K18: 0.25 | L18: 2 | M18: 4 | N18: =J18*K18*L18*M18 -> 0.5
C19: Construction Foreman | D19: 1 | E19: 6 | F19: 615 | G19: =F19*E19*D19 -> 3690 | J19: L | K19: W | L19: T | N19: VOLUME
C20: Skilled Worker ( Carpenter ) | D20: 1 | E20: =E19 -> 6 | F20: 414 | G20: =F20*E20*D20 -> 2484 | J20: 3 | K20: 6 | L20: 0.1 | M20: 1 | N20: =J20*K20*L20*M20 -> 1.8
C21: Skilled Worker ( Mason ) | D21: 3 | E21: =E20 -> 6 | F21: 390 | G21: =F21*E21*D21 -> 7020
C22: Laborer | D22: 5 | E22: =E21 -> 6 | F22: 341 | G22: =F22*E22*D22 -> 10230
F23: SUB TOTAL = | G23: =SUM(G19:G22) -> 23424 | H23: =G23/G32 -> 0.36804726
A24: Materials | H24: 1
D25: QUANTITY | E25: UNITS | F25: UNIT COST | G25: AMOUNT | H25: =#REF! -> #REF!
H26: =H15*H16*H24*H25 -> #REF!
C27: Premium Portland Cement ASTM C595 | D27: =ROUNDUP(D$15*9,0) -> 87 | E27: bags | F27: 310 | G27: =F27*D27 -> 26970
C28: W. Sand | D28: 10 | E28: cu.m. | F28: 600 | G28: =F28*D28 -> 6000
C29: Gravel 3/4", Crushed | D29: 5 | E29: cu.m. | F29: 1450 | G29: =F29*D29 -> 7250
F30: SUB TOTAL = | G30: =SUM(G27:G29) -> 40220
F32: DIRECT COST= | G32: =G30+G23 -> 63644
F33: UNIT COST = | G33: =G32/D15 -> 6599.3364
A35: II | B35: REINFORCE STEEL BAR | C35: QUANTITY = | D35: =D46*0.616+D47*0.888 -> 30.712 | E35: kgs | H35: 0.4 | J35: VERT
H36: 0.4 | J36: l | K36: PCS | L36: LN.M.
A37: Labor | J37: 3 | K37: =110/0.4 -> 275 | L37: =J37*K37 -> 825
D38: NO. OF PERSONS | E38: NO. OF HOURS | F38: RATE PER HOUR | G38: AMOUNT
C39: Construction Foreman | D39: 1 | E39: 6 | F39: 615 | G39: =F39*E39*D39 -> 3690 | J39: HOR .BAR
C40: Skilled Worker ( Steel Man ) | D40: 2 | E40: =E39 -> 6 | F40: 390 | G40: =F40*E40*D40 -> 4680 | J40: 110 | K40: 10 | L40: =J40*K40 -> 1100
C41: Laborer | D41: 3 | E41: =E40 -> 6 | F41: 341 | G41: =F41*E41*D41 -> 6138
F42: SUB TOTAL = | G42: =SUM(G39:G41) -> 14508 | H42: =G42/G52 -> 0.53322552 | J42: PLANKS
A43: Materials | H43: 1 | J43: l | K43: PCS | L43: LN.M.
D44: QUANTITY | E44: UNITS | F44: UNIT COST | G44: AMOUNT | H44: =#REF! -> #REF! | J44: 4 | K44: 110 | L44: =J44*K44 -> 440
H45: =H35*H36*H43*H44 -> #REF!
C46: 10mm diam x 6m corr. Deform bar | D46: 34 | E46: length | F46: 210 | G46: =F46*D46 -> 7140
C47: 12mm diam x 6m corr. Deform bar | D47: 11 | E47: length | F47: 310 | G47: =F47*D47 -> 3410
...

Sheet BAGONG LIP.
A1: Republic of the Philippines
A2: Province of South Cotabato | H2: =J270 -> 0.46808423
A3: City of Koronadal | H3: =H352 -> -5719.762
A4: CITY MAYORS OFFICE - BARANGAY DEVELOPMENT PROGRAM
A6: Project: | B6: RENOVATION OF DAY CARE CENTER AT BAGONG LIPUNAN BARANGAY SAN ISIDRO
A7: Location:
A8: Project Cost Php: | B8: 400000
A10: PROGRAM OF WORKS
A12: ITEM | B12: SCOPE OF WORKS
A15: I | B15: STRUCTURAL CONCRETE | C15: QUANTITY = | D15: =N16+N18+N20 -> 2.444 | E15: cu.m. | H15: 0.4 | J15: L | K15: W | L15: T | N15: VOLUME
H16: 0.4 | J16: 0.6 | K16: 0.6 | L16: 0.1 | M16: 4 | N16: =J16*K16*L16*M16 -> 0.144
A17: Labor | J17: L | K17: W | L17: T | N17: VOLUME
D18: NO. OF PERSONS | E18: NO. OF HOURS | F18: RATE PER HOUR | G18: AMOUNT | J18: 0.25 | K18: 0.25 | L18: 2 | M18: 4 | N18: =J18*K18*L18*M18 -> 0.5
C19: Construction Foreman | D19: 1 | E19: 6 | F19: 718 | G19: =F19*E19*D19 -> 4308 | J19: L | K19: W | L19: T | N19: VOLUME
C20: Skilled Worker ( Carpenter ) | D20: 1 | E20: =E19 -> 6 | F20: 528.8 | G20: =F20*E20*D20 -> 3172.8 | J20: 3 | K20: 6 | L20: 0.1 | M20: 1 | N20: =J20*K20*L20*M20 -> 1.8
C21: Skilled Worker ( Mason ) | D21: 2 | E21: =E20 -> 6 | F21: 490.72 | G21: =F21*E21*D21 -> 5888.64
C22: Laborer | D22: 2 | E22: =E21 -> 6 | F22: 442.5 | G22: =F22*E22*D22 -> 5310
F23: SUB TOTAL = | G23: =SUM(G19:G22) -> 18679.44 | H23: =G23/G32 -> 0.47446547
A24: Materials | H24: 1
D25: QUANTITY | E25: UNITS | F25: UNIT COST | G25: AMOUNT | H25: =#REF! -> #REF!
H26: =H15*H16*H24*H25 -> #REF!
C27: Premium Portland Cement ASTM C595 | D27: =ROUNDUP(D$15*9.5,0) -> 24 | E27: bags | F27: 310 | G27: =F27*D27 -> 7440
C28: W. Sand | D28: 10 | E28: cu.m. | F28: 600 | G28: =F28*D28 -> 6000
C29: Gravel 3/4", Crushed | D29: 5 | E29: cu.m. | F29: 1450 | G29: =F29*D29 -> 7250
F30: SUB TOTAL = | G30: =SUM(G27:G29) -> 20690
F32: DIRECT COST= | G32: =G30+G23 -> 39369.44
F33: UNIT COST = | G33: =G32/D15 -> 16108.609
A35: II | B35: REINFORCE STEEL BAR | C35: QUANTITY = | D35: =SUM(L37,L40,L44,)*0.616 -> 1456.84 | E35: kgs | H35: 0.4 | J35: VERT
H36: 0.4 | J36: l | K36: PCS | L36: LN.M.
A37: Labor | J37: 3 | K37: =110/0.4 -> 275 | L37: =J37*K37 -> 825
D38: NO. OF PERSONS | E38: NO. OF HOURS | F38: RATE PER HOUR | G38: AMOUNT
C39: Construction Foreman | D39: 1 | E39: 4 | F39: 718 | G39: =F39*E39*D39 -> 2872 | J39: HOR .BAR
C40: Skilled Worker ( Steel Man ) | D40: 1 | E40: =E39 -> 4 | F40: 490.72 | G40: =F40*E40*D40 -> 1962.88 | J40: 110 | K40: 10 | L40: =J40*K40 -> 1100
C41: Laborer | D41: 2 | E41: =E40 -> 4 | F41: 442.5 | G41: =F41*E41*D41 -> 3540
F42: SUB TOTAL = | G42: =SUM(G39:G41) -> 8374.88 | H42: =G42/G52 -> 0.45404904 | J42: PLANKS
A43: Materials | H43: 1 | J43: l | K43: PCS | L43: LN.M.
D44: QUANTITY | E44: UNITS | F44: UNIT COST | G44: AMOUNT | H44: =#REF! -> #REF! | J44: 4 | K44: 110 | L44: =J44*K44 -> 440
H45: =H35*H36*H43*H44 -> #REF!
C46: 10mm diam x 6m corr. Deform bar | D46: 20 | E46: length | F46: 210 | G46: =F46*D46 -> 4200
C47: 12mm diam x 6m corr. Deform bar | D47: 12 | E47: length | F47: 310 | G47: =F47*D47 -> 3720
...

Sheet MPDP
A1: Republic of the Philippines
A2: Province of South Cotabato
A3: City of Koronadal | O3: =(24*4+2.4*5) -> 108
A4: CITY MAYORS OFFICE - BARANGAY DEVELOPMENT PROGRAM | H4: direc cost | I4: =G24+G61+G102+G160 -> 180296.24 | L4: =E19+E43+E90++E151 -> 13 | M4: hours | N4: =(5*6+2.4*9) -> 51.6
H5: materials | I5: =G163 -> 218915.68 | L5: =L4 -> 13 | M5: wd
A6: Project Title: | B6: CONSTRUCTION OF SEPTIC TANK | H6: labor | I6: =G164 -> 161084.32 | J6: =I6/I4 -> 0.89344248 | N6: =I5*0.45 -> 98512.056
A7: Location: | B7: CITY OF KORONADAL, PUBLIC MARKET | I7: =I5+I6 -> 380000
A8: Project Cost: | B8: =G165 -> 380000 | P8: =500000-I6 -> 338915.68
A9: Duration: | B9: =E21+E32+E43+E69+E90+E109+E152+E134 -> 38 | C9: Working Days | P9: =500000-I7 -> 120000
A11: PROGRAM OF WORKS
A13: ITEM | B13: SCOPE OF WORKS
A15: I | B15: SITE SURVEY, LAYOUT AND | C15: QUANTITY = | D15: 1 | E15: ls
B16: INSTALLATION OF BARRACADE
A17: Labor
D18: NO. OF PERSONS | E18: NO. OF DAYS | F18: RATE PER DAY | G18: AMOUNT | J18: l | K18: w | L18: h | M18: volume | N18: 20% shrinkage | O18: total volume
C19: Construction Foreman | D19: 1 | E19: 2 | F19: 718 | G19: =F19*E19*D19 -> 1436 | J19: 30 | K19: 15 | L19: 0.2 | M19: =J19*K19*L19 -> 90 | N19: =M19*0.2 -> 18 | O19: =N19+M19 -> 108
C20: Skilled Worker | D20: 1 | E20: 2 | F20: 490.72 | G20: =F20*E20*D20 -> 981.44
C21: Laborer | D21: 4 | E21: 2 | F21: 442.5 | G21: =F21*E21*D21 -> 3540
F22: SUB TOTAL = | G22: =SUM(G19:G21) -> 5957.44 | H22: =#REF!*#REF! -> #REF! | I22: =G22/#REF! -> #REF!
F24: DIRECT COST= | G24: =G22 -> 5957.44
F25: UNIT COST = | G25: =G24/D15 -> 5957.44
A27: II | B27: DEMOLITION AND EXCAVATION | C27: QUANTITY = | D27: 70 | E27: cu.m.
A29: Labor
D30: NO. OF PERSONS | E30: NO. OF DAYS | F30: RATE PER DAY | G30: AMOUNT
C31: Construction Foreman | D31: 1 | E31: 10 | F31: 718 | G31: =F31*E31*D31 -> 7180
C32: Skilled Worker | D32: 2 | E32: 10 | F32: 490.72 | G32: =F32*E32*D32 -> 9814.4
C33: Laborer | D33: 6 | E33: 10 | F33: 442.5 | G33: =F33*E33*D33 -> 26550
F34: SUB TOTAL = | G34: =SUM(G31:G33) -> 43544.4
F36: DIRECT COST= | G36: =G34 -> 43544.4
F37: UNIT COST = | G37: =G36/D27 -> 622.06286
A39: III | B39: FORMWORKS | C39: QUANTITY = | D39: 1 | E39: ls
A41: Labor
D42: NO. OF PERSONS | E42: NO. OF DAYS | F42: RATE PER DAY | G42: AMOUNT
C43: Construction Foreman | D43: 1 | E43: 4 | F43: 718 | G43: =F43*E43*D43 -> 2872
C44: Skilled Worker | D44: 2 | E44: 4 | F44: 528.8 | G44: =F44*E44*D44 -> 4230.4
C45: Laborer | D45: 6 | E45: 4 | F45: 442.5 | G45: =F45*E45*D45 -> 10620
F46: SUB TOTAL = | G46: =SUM(G43:G45) -> 17722.4 | H46: =H59*G59 -> 25408.35
A47: Materials
D48: QUANTITY | E48: UNITS | F48: UNIT COST | G48: AMOUNT
C50: Marine Plywood 10mmx4'x8' | D50: 55 | E50: sheets | F50: 920 | G50: =F50*D50 -> 50600
...

Sheet POW COVER
B1: Republic of the Philippines
B2: Province of South Cotabato
B3: City of Koronadal
B4: OFFICE OF THE CITY ENGINEER
B7: PROGRAM OF WORK/BUDGET COST FOR KORONADAL CITY INFRASTRUCTURE PROJECTS
B9: PROJECT: | E9: Construction of Covered Pathway at City hall Entrance/Exit ( 29 SPAN, 3m length/span) | Q9: Date: | X9: Construction of Covered Pathway at City hall Entrance/Exit
E10: ( 29 SPAN, 3m length/span) | Q10: Net Length:
B11: Location: | E11: CITY HALL SITE, CITY OF KORONADAL | Q11: Classification:
Q12: Starting Date: | S12: Upon Approval
B13: Estimated Project Cost: | E13: =S55 -> 1100000 | Q13: Total Project Duration: | T13: ='PROJECT DETAILS'!B4 -> 200 | U13: C.D.
B14: Source of Fund: | E14: ='PROJECT DETAILS'!B6:I6 -> 0 | Q14: No. of Working Days:
Q15: No. of Pre-determined:
B16: Project limits: | Q16: Unworkable Days:
A18: ITEM | B18: ITEM NO. | D18: DESCRIPTION OF WORK | N18: % OF | O18: EQUIPMENT | V18: COST
N19: TOTAL | O19: DESCRIPTION | R19: REQUIRED
A20: 1 | B20: 803 | D20: Structural excavation | N20: =T37/Y37 -> #REF! | S20: ='PROJECT DETAILS'!E232 -> 1 | V20: ='PROJECT DETAILS'!I232 -> 1
A21: 2 | B21: SPL - 3 | D21: Formworks | N21: =T38/Y38 -> #REF! | O21: Concrete Mixer One Bagger | S21: ='PROJECT DETAILS'!E233 -> 1 | V21: ='PROJECT DETAILS'!I233 -> 1
A22: 3 | B22: 900(7) | D22: Reinforce Concrete | N22: =T39/Y39 -> #REF! | O22: Conrete Vibrator | S22: ='PROJECT DETAILS'!E234 -> 1 | V22: ='PROJECT DETAILS'!I234 -> 1
B23: 1047 | D23: Steel Works ( support ) ( 6.5m ) | N23: =T40/Y40 -> #DIV/0!
A24: 4 | B24: 1047(1) | D24: Steel Works ( GIRT 1 ) ( 13.41m ) | N24: =T41/Y41 -> #DIV/0! | O24: Electric drill | S24: 1 | V24: ='PROJECT DETAILS'!I235 -> 1
B25: 1047(2) | D25: Steel Works ( GIRT 2 ) ( 12.13m ) | N25: =T42/Y42 -> #DIV/0!
B26: 1047(3) | D26: Steel Works ( TRUSS 1 ) ( 9.74m ) | N26: =T43/Y43 -> #REF!
A27: 5 | B27: 903(1) | D27: Roofing Works | N27: =T44/Y44 -> #REF! | O27: Electric Bar Cutter and Bar bender | S27: ='PROJECT DETAILS'!E235 -> 1 | V27: ='PROJECT DETAILS'!I236 -> 2
A28: 6 | B28: 1027 | D28: Painting Works | N28: =T45/Y45 -> #REF! | O28: Welding Machine | S28: ='PROJECT DETAILS'!E236 -> 2 | V28: ='PROJECT DETAILS'!I237 -> 1
A29: 13 | B29: SPL - 2 | D29: Billboards | N29: =T46/Y46 -> #REF! | V29: ='PROJECT DETAILS'!I244 -> 0
B30: SPL - 8 | D30: Mobilization / Demobilization | N30: =#REF!/#REF! -> #REF!
A31: 15 | B31: SPL -4 | D31: Construction of Safety and Health Program | N31: =T48/Y48 -> #DIV/0! | V31: ='PROJECT DETAILS'!I246 -> 0
B33: ESTIMATED COST OF PROPOSED WORK
B34: ITEM NO. | D34: DESCRIPTION | H34: LABOR | I34: MATERIALS | J34: OCM | K34: PROFIT | L34: VAT | M34: QUANTITY | O34: UNIT | Q34: TOTAL DIRECT COST | R34: UNIT COST | T34: ADJUSTED
T35: COST
A37: 1 | B37: =B20 -> 803 | D37: =D20 -> Structural excavation | H37: ='ITEM 1'!X16 -> 3584 | I37: ='ITEM 1'!X26 -> 0 | J37: ='ITEM 1'!AD28 -> 537.6 | K37: ='ITEM 1'!AD29 -> 358.4 | L37: ='ITEM 1'!AD30 -> 224 | M37: 29.41 | O37: ='SUMMARIZE QUANTITY'!C3 -> cu.m. | Q37: ='ITEM 1'!AD27 -> 3584 | R37: ='ITEM 1'!AD32 -> 159.9456 | T37: =R37*M37 -> 4704 | Y37: =S49 -> #REF!
A38: 2 | B38: =B21 -> SPL - 3 | D38: =D21 -> Formworks | H38: ='ITEM 2'!X16 -> 0 | I38: ='ITEM 2'!X34 -> 0 | J38: ='ITEM 2'!AD36 -> 0 | K38: ='ITEM 2'!AD37 -> 0 | L38: ='ITEM 2'!AD38 -> 0 | M38: 300 | O38: bd.ft. | Q38: ='ITEM 2'!AD35 -> 0 | R38: ='ITEM 2'!AD40 -> 0 | T38: =R38*M38 -> 0 | Y38: =S49 -> #REF!
A39: 3 | B39: =B22 -> 900(7) | D39: =D22 -> Reinforce Concrete | H39: ='ITEM 3'!X16 -> 0 | I39: ='ITEM 3'!X38 -> 0 | J39: ='ITEM 3'!AD40 -> 0 | K39: ='ITEM 3'!AD41 -> 0 | L39: ='ITEM 3'!AD42 -> 0 | M39: 8.721 | O39: ='SUMMARIZE QUANTITY'!C6 -> cu.m. | Q39: ='ITEM 3'!AD39 -> 0 | R39: ='ITEM 3'!AD44 -> 0 | T39: =R39*M39 -> 0 | Y39: =S49 -> #REF!
A40: 4 | B40: =B23 -> 1047 | D40: =D23 -> Steel Works ( support ) ( 6.5m ) | M40: 18 | O40: sets | T40: =R40*M40 -> 0
A41: 5 | B41: =B24 -> 1047(1) | D41: =D24 -> Steel Works ( GIRT 1 ) ( 13.41m ) | M41: 17 | O41: sets | T41: =R41*M41 -> 0
A42: 6 | B42: =B25 -> 1047(2) | D42: =D25 -> Steel Works ( GIRT 2 ) ( 12.13m ) | M42: 17 | O42: sets | T42: =R42*M42 -> 0
A43: 7 | B43: =B26 -> 1047(3) | D43: =D26 -> Steel Works ( TRUSS 1 ) ( 9.74m ) | H43: ='ITEM 4'!X16 -> 0 | I43: ='ITEM 4'!X36 -> 0 | J43: ='ITEM 4'!AD38 -> 0 | K43: ='ITEM 4'!AD39 -> 0 | L43: ='ITEM 4'!AD40 -> 0 | M43: 18 | O43: sets | Q43: ='ITEM 4'!AD37:AD37 -> 0 | R43: ='ITEM 4'!AD42 -> 0 | T43: =R43*M43 -> 0 | Y43: =S49 -> #REF!
A44: 8 | B44: =B27 -> 903(1) | D44: =D27 -> Roofing Works | H44: ='ITEM 5'!X16 -> 0 | I44: ='ITEM 5'!X36 -> 0 | J44: ='ITEM 5'!AD38 -> 0 | K44: ='ITEM 5'!AD39 -> 0 | L44: ='ITEM 5'!AD40 -> 0 | M44: 165.24 | O44: sq.m. | Q44: ='ITEM 5'!AD37 -> 0 | R44: ='ITEM 5'!AD42 -> 0 | T44: =R44*M44 -> 0 | Y44: =S49 -> #REF! | AA44: 1447461.6
A45: 9 | B45: =B28 -> 1027 | D45: =D28 -> Painting Works | H45: ='ITEM 6'!X16 -> 0 | I45: ='ITEM 6'!X34 -> 0 | J45: ='ITEM 6'!AD36 -> 0 | K45: ='ITEM 6'!AD37 -> 0 | L45: ='ITEM 6'!AD38 -> 0 | M45: 1 | O45: lumpsum | Q45: ='ITEM 6'!AD35 -> 0 | R45: ='ITEM 6'!AD40 -> 0 | T45: =R45*M45 -> 0 | Y45: =S49 -> #REF!
A46: 10 | B46: =B29 -> SPL - 2 | D46: =D29 -> Billboards | H46: =#REF! -> #REF! | I46: =#REF! -> #REF! | J46: =#REF! -> #REF! | K46: =#REF! -> #REF! | L46: =#REF! -> #REF! | M46: ='SUMMARIZE QUANTITY'!B37 -> 1 | O46: lumpsum | Q46: =#REF! -> #REF! | R46: =#REF! -> #REF! | T46: =R46*M46 -> #REF! | Y46: =S49 -> #REF!
...

Sheet ITEM 1
A1: DETAILED UNIT PRICE ANALYSIS
A3: PROJECT | E3: : | F3: ='POW COVER'!E9 -> Construction of Covered Pathway at City hall Entrance/Exit ( 29 SPAN, 3m length/span)
A4: Item No. | E4: : | F4: ='POW COVER'!B37 -> 803
A5: Description | E5: : | F5: ='POW COVER'!D37 -> Structural excavation
A6: Quantity | E6: : | F6: ='POW COVER'!M37 -> 29.41 | G6: ='POW COVER'!O37 -> cu.m. | I6: sets
A7: Output Per Hour: | F7: =F6/AF9 -> 1.838125 | G7: =""&G6&" per hour" -> cu.m. per hour | AF7: 10
AF8: hours
B9: Designation | N9: No. of Person | Q9: No. of Hours | T9: Houry Rate | X9: AMOUNT | AF9: =MAX(Q12:S15,Q20:S20) -> 16
A10: A. | B10: Labor
B12: a. Construction Foreman | N12: 1 | Q12: 16 | T12: 60 | X12: =T12*Q12*N12 -> 960
B13: b. Skilled Labor | N13: 2 | Q13: 16 | T13: 43.75 | X13: =T13*Q13*N13 -> 1400
B14: c. Unskilled Labor | N14: 2 | Q14: 16 | T14: 38.25 | X14: =T14*Q14*N14 -> 1224
A16: Sub Total for A | X16: =SUM(X12:AC15) -> 3584
B17: Name & Capacity | N17: No. of units | Q17: No. of Hours | T17: Houry Rate | X17: AMOUNT
A18: B. | B18: Equipment
A21: Sub Total for B | X21: =SUM(X20:AC20) -> 0
B22: Name & Specifications | N22: Units | Q22: Quantity | T22: Unit cost | X22: AMOUNT
A23: C. | B23: Materials
A26: Sub-Total for C | X26: =SUM(X25:AC25) -> 0
A27: D. | B27: Total Direct Cost | U27: A+B+C | X27: =X26+X21+X16 -> 3584 | AD27: =X27 -> 3584
A28: E. | B28: Overhead,Contingencies and Miscellaneous | O28: (OCM) | U28: 15% of D | X28: =0.15*X27 -> 537.6 | AD28: =X28 -> 537.6
A29: F. | B29: Contractor's Profit (CP) | U29: 10%of D | X29: =0.1*X27 -> 358.4 | AD29: =X29 -> 358.4
A30: G. | B30: Value Added Tax (VAT) | T30: 5%*(D+E+F) | X30: =0.05*(X29+X28+X27) -> 224 | AD30: =X30 -> 224
A31: H. | B31: Total Cost | T31: (D+E+F+G) | X31: =X30+X29+X28+X27 -> 4704 | AD31: =X31 -> 4704
A32: I. | B32: Total Unit Cost | U32: H/Qty. | X32: =X31/F6 -> 159.9456 | AD32: =X32 -> 159.9456

Sheet ITEM 2
A1: DETAILED UNIT PRICE ANALYSIS
A3: PROJECT | E3: : | F3: ='POW COVER'!E9 -> Construction of Covered Pathway at City hall Entrance/Exit ( 29 SPAN, 3m length/span)
A4: Item No. | E4: : | F4: ='POW COVER'!B38 -> SPL - 3
A5: Description | E5: : | F5: ='POW COVER'!D38 -> Formworks
A6: Quantity | E6: : | F6: ='POW COVER'!M38 -> 300 | G6: sq.m. | I6: sets
A7: Output Per Hour: | F7: 4 | G7: =""&G6&" per hour" -> sq.m. per hour
AF8: hours
B9: Designation | N9: No. of Person | Q9: No. of Hours | T9: Houry Rate | X9: AMOUNT | AF9: =MAX(Q12:S15,Q20:S20) -> 0
A10: A. | B10: Labor
B12: a. Construction Foreman | X12: =T12*Q12*N12 -> 0
B13: b. Skilled Labor ( Welder ) | X13: =T13*Q13*O13 -> 0
B14: c. Unskilled Labor | X14: =T14*Q14*O14 -> 0
X15: =T15*Q15*O15 -> 0
A16: Sub Total for A | X16: =SUM(X12:AC15) -> 0
B17: Name & Capacity | N17: No. of units | Q17: No. of Hours | T17: Houry Rate | X17: AMOUNT
A18: B. | B18: Equipment
A21: Sub Total for B | X21: =SUM(X20:AC20) -> 0
B22: Name & Specifications | N22: Units | Q22: Quantity | T22: Unit cost | X22: AMOUNT
A23: C. | B23: Materials
B25: 100 coco-lumber ( 2x3x12 ) | N25: bd.ft | Q25: 600 | X25: =T25*Q25 -> 0
B26: 100 coco lumber (2x2x12) | N26: bd.ft | Q26: 400 | X26: =T26*Q26 -> 0
B27: Marine plywood | N27: sht | Q27: 10 | X27: =T27*Q27 -> 0
B28: Leveling Hose | N28: m | Q28: 20 | X28: =T28*Q28 -> 0
B29: Nylon string | N29: roll | Q29: 15 | X29: =T29*Q29 -> 0
B30: CWN 4" | N30: kgs. | Q30: 15 | X30: =T30*Q30 -> 0
B31: CWN 2 1/2" | N31: kgs. | Q31: 15 | X31: =T31*Q31 -> 0
B32: CWN 1 1/2" | N32: kgs. | Q32: 5 | X32: =T32*Q32 -> 0
A34: Sub-Total for C | X34: =SUM(X25:AC33) -> 0
A35: D. | B35: Total Direct Cost | U35: A+B+C | X35: =X34+X21+X16 -> 0 | AD35: =X35 -> 0
A36: E. | B36: Overhead,Contingencies and Miscellaneous | O36: (OCM) | U36: 15% of D | X36: =0.15*X35 -> 0 | AD36: =X36 -> 0
A37: F. | B37: Contractor's Profit (CP) | U37: 10%of D | X37: =0.1*X35 -> 0 | AD37: =X37 -> 0
A38: G. | B38: Value Added Tax (VAT) | T38: 5%*(D+E+F) | X38: =0.05*(X37+X36+X35) -> 0 | AD38: =X38 -> 0
A39: H. | B39: Total Cost | T39: (D+E+F+G) | X39: =X38+X37+X36+X35 -> 0 | AD39: =X39 -> 0
A40: I. | B40: Total Unit Cost | U40: H/Qty. | X40: =X39/F6 -> 0 | AD40: =X40 -> 0

Sheet ITEM 3
A1: DETAILED UNIT PRICE ANALYSIS
A3: PROJECT | E3: : | F3: ='POW COVER'!E9 -> Construction of Covered Pathway at City hall Entrance/Exit ( 29 SPAN, 3m length/span)
A4: Item No. | E4: : | F4: ='POW COVER'!B39 -> 900(7)
A5: Description | E5: : | F5: ='POW COVER'!D39 -> Reinforce Concrete
A6: Quantity | E6: : | F6: ='POW COVER'!M39 -> 8.721 | G6: ='POW COVER'!O39 -> cu.m. | I6: sets
A7: Output Per Hour: | F7: 2 | G7: =""&G6&" per hour" -> cu.m. per hour
AF8: hours
B9: Designation | N9: No. of Person | Q9: No. of Hours | T9: Houry Rate | X9: AMOUNT | AF9: =MAX(Q12:S15,Q20:S23) -> 0
A10: A. | B10: Labor
B12: a. Construction Foreman | X12: =T12*Q12*N12 -> 0
B13: b. Skilled Labor ( Welder ) | X13: =T13*Q13*O13 -> 0
B14: c. Unskilled Labor | X14: =T14*Q14*O14 -> 0
A16: Sub Total for A | X16: =SUM(X12:AC15) -> 0
B17: Name & Capacity | N17: No. of units | Q17: No. of Hours | T17: Houry Rate | X17: AMOUNT
A18: B. | B18: Equipment
B20: Concrete Vibrator | X20: =T20*Q20*N20 -> 0
B21: Concrete Mixer one bagger | X21: =T21*Q21*N21 -> 0
B22: Electric Bar Cutter and Bar bender | X22: =T22*Q22*N22 -> 0
A24: Sub Total for B | X24: =SUM(X20:AC23) -> 0
B25: Name & Specifications | N25: Units | Q25: Quantity | T25: Unit cost | X25: AMOUNT
A26: C. | B26: Materials
B28: Cement | N28: bag | Q28: 84 | X28: =T28*Q28 -> 0
B29: 12mm RSB | N29: length | Q29: 75 | X29: =T29*Q29 -> 0
B30: 10mm RSB | N30: length | Q30: 72 | X30: =T30*Q30 -> 0
B31: Sand | N31: cu.m. | Q31: =8.72*0.5 -> 4.36 | X31: =T31*Q31 -> 0
B32: Empty container | N32: pc | Q32: 10 | X32: =T32*Q32 -> 0
B33: tie wire GA. 16 | N33: kgs | Q33: 10 | X33: =T33*Q33 -> 0
B34: Gravel 3/4 | N34: cu.m. | Q34: 8.72 | X34: =T34*Q34 -> 0
B35: Anchor bolt w/ nut & washer ( 12mm ) | N35: pcs | Q35: 11 | X35: =T35*Q35 -> 0
B36: Steel Plate ( 6mm ) | N36: sq.m. | Q36: 1.35 | X36: =T36*Q36 -> 0
A38: Sub-Total for C | X38: =SUM(X28:AC37) -> 0
A39: D. | B39: Total Direct Cost | U39: A+B+C | X39: =X38+X24+X16 -> 0 | AD39: =X39 -> 0
A40: E. | B40: Overhead,Contingencies and Miscellaneous | O40: (OCM) | U40: 15% of D | X40: =0.15*X39 -> 0 | AD40: =X40 -> 0
A41: F. | B41: Contractor's Profit (CP) | U41: 10%of D | X41: =0.1*X39 -> 0 | AD41: =X41 -> 0
A42: G. | B42: Value Added Tax (VAT) | T42: 5%*(D+E+F) | X42: =0.05*(X41+X40+X39) -> 0 | AD42: =X42 -> 0
A43: H. | B43: Total Cost | T43: (D+E+F+G) | X43: =X42+X41+X40+X39 -> 0 | AD43: =X43 -> 0
A44: I. | B44: Total Unit Cost | U44: H/Qty. | X44: =X43/F6 -> 0 | AD44: =X44 -> 0

Sheet ITEM 4
A1: DETAILED UNIT PRICE ANALYSIS
A3: PROJECT | E3: : | F3: ='POW COVER'!E9 -> Construction of Covered Pathway at City hall Entrance/Exit ( 29 SPAN, 3m length/span)
A4: Item No. | E4: : | F4: ='POW COVER'!B40 -> 1047
A5: Description | E5: : | F5: ='POW COVER'!D40 -> Steel Works ( support ) ( 6.5m )
A6: Quantity | E6: : | F6: ='POW COVER'!M40 -> 18 | G6: ='POW COVER'!O40 -> sets | I6: sets
A7: Output Per Hour: | F7: 0.1 | G7: =""&G6&" per hour" -> sets per hour
AF8: hours
B9: Designation | N9: No. of Person | Q9: No. of Hours | T9: Houry Rate | X9: AMOUNT | AF9: =MAX(Q12:S15,Q20:S22) -> 0
A10: A. | B10: Labor
B12: a. Construction Foreman | X12: =T12*Q12*N12 -> 0
B13: b. Skilled Labor ( Welder ) | X13: =T13*Q13*O13 -> 0
B14: c. Unskilled Labor | X14: =T14*Q14*O14 -> 0
X15: =T15*Q15*O15 -> 0
A16: Sub Total for A | X16: =SUM(X12:AC15) -> 0
B17: Name & Capacity | N17: No. of units | Q17: No. of Hours | T17: Houry Rate | X17: AMOUNT
A18: B. | B18: Equipment
B20: Welding Machine | X20: =T20*Q20*N20 -> 0
B21: Electric Sander | X21: =T21*Q21*N21 -> 0
A23: Sub Total for B | X23: =SUM(X20:AC22) -> 0
B24: Name & Specifications | N24: Units | Q24: Quantity | T24: Unit cost | X24: AMOUNT
A25: C. | B25: Materials
B27: G.I. Pipe 2 diam. Schd. 20 | N27: length | X27: =T27*Q27 -> 0
B28: G.I. Pipe 1 1/2 diam. Schd. 20 | N28: length | X28: =T28*Q28 -> 0
B29: G.I. Pipe 1 diam. Schd. 20 | N29: length | X29: =T29*Q29 -> 0
B30: Angle Bar ( 1/4 x 1 1/2 ) | N30: length | X30: =T30*Q30 -> 0
B31: Angle Bar ( 1/4 x 1 1/4 ) | N31: length | X31: =T31*Q31 -> 0
B32: Angle Bar ( 1/4 x 1 ) | N32: length | X32: =T32*Q32 -> 0
B33: Welding Rod | N33: kgs | X33: =T33*Q33 -> 0
B34: Cut Off Wheel Blade # 14" | N34: pcs | X34: =T34*Q34 -> 0
A36: Sub-Total for C | X36: =SUM(X27:AC35) -> 0
A37: D. | B37: Total Direct Cost | U37: A+B+C | X37: =X36+X23+X16 -> 0 | AD37: =X37 -> 0
A38: E. | B38: Overhead,Contingencies and Miscellaneous | O38: (OCM) | U38: 15% of D | X38: =0.15*X37 -> 0 | AD38: =X38 -> 0
A39: F. | B39: Contractor's Profit (CP) | U39: 10%of D | X39: =0.1*X37 -> 0 | AD39: =X39 -> 0
A40: G. | B40: Value Added Tax (VAT) | T40: 5%*(D+E+F) | X40: =0.05*(X39+X38+X37) -> 0 | AD40: =X40 -> 0
A41: H. | B41: Total Cost | T41: (D+E+F+G) | X41: =X40+X39+X38+X37 -> 0 | AD41: =X41 -> 0
A42: I. | B42: Total Unit Cost | U42: H/Qty. | X42: =X41/F6 -> 0 | AD42: =X42 -> 0

Sheet ITEM 5
A1: DETAILED UNIT PRICE ANALYSIS
A3: PROJECT | E3: : | F3: ='POW COVER'!E9 -> Construction of Covered Pathway at City hall Entrance/Exit ( 29 SPAN, 3m length/span)
A4: Item No. | E4: : | F4: ='POW COVER'!B41 -> 1047(1)
A5: Description | E5: : | F5: ='POW COVER'!D41 -> Steel Works ( GIRT 1 ) ( 13.41m )
A6: Quantity | E6: : | F6: ='POW COVER'!M41 -> 17 | G6: ='POW COVER'!O41 -> sets | I6: sets
A7: Output Per Hour: | F7: 15 | G7: =""&G6&" per hour" -> sets per hour
AF8: hours
B9: Designation | N9: No. of Person | Q9: No. of Hours | T9: Houry Rate | X9: AMOUNT | AF9: =MAX(Q12:S15,Q20:S23) -> 0
A10: A. | B10: Labor
B12: a. Construction Foreman | X12: =T12*Q12*N12 -> 0
B13: b. Skilled Labor ( Welder ) | X13: =T13*Q13*O13 -> 0
B14: c. Unskilled Labor | X14: =T14*Q14*O14 -> 0
X15: =T15*Q15*O15 -> 0
A16: Sub Total for A | X16: =SUM(X12:AC15) -> 0
B17: Name & Capacity | N17: No. of units | Q17: No. of Hours | T17: Houry Rate | X17: AMOUNT
A18: B. | B18: Equipment
B20: Welding Machine | X20: =T20*Q20*N20 -> 0
B21: Electric sander | X21: =T21*Q21*N21 -> 0
B22: Electric drill | X22: =T22*Q22*N22 -> 0
A24: Sub Total for B | X24: =SUM(X20:AC23) -> 0
B25: Name & Specifications | N25: Units | Q25: Quantity | T25: Unit cost | X25: AMOUNT
A26: C. | B26: Materials
B28: PRE Painted rib type Long Span ( 0.40mm) | N28: ln.m. | X28: =T28*Q28 -> 0
B29: PRE Fabricated rib type Blind gutter ( 0.40mm) | N29: ln.m. | X29: =T29*Q29 -> 0
B30: 2x3x1.2mm CEE purlins | N30: length | X30: =T30*Q30 -> 0
B31: tex crew 2 1/2 | N31: pcs | X31: =T31*Q31 -> 0
B32: Vulcaseal | N32: qrt | X32: =T32*Q32 -> 0
B33: welding rod ( N 1630 ) | N33: kl | X33: =T33*Q33 -> 0
B34: cutting disc | N34: pc | X34: =T34*Q34 -> 0
A36: Sub-Total for C | X36: =SUM(X28:AC35) -> 0
A37: D. | B37: Total Direct Cost | U37: A+B+C | X37: =X36+X24+X16 -> 0 | AD37: =X37 -> 0
A38: E. | B38: Overhead,Contingencies and Miscellaneous | O38: (OCM) | U38: 15% of D | X38: =0.15*X37 -> 0 | AD38: =X38 -> 0
A39: F. | B39: Contractor's Profit (CP) | U39: 10%of D | X39: =0.1*X37 -> 0 | AD39: =X39 -> 0
A40: G. | B40: Value Added Tax (VAT) | T40: 5%*(D+E+F) | X40: =0.05*(X39+X38+X37) -> 0 | AD40: =X40 -> 0
A41: H. | B41: Total Cost | T41: (D+E+F+G) | X41: =X40+X39+X38+X37 -> 0 | AD41: =X41 -> 0
A42: I. | B42: Total Unit Cost | U42: H/Qty. | X42: =X41/F6 -> 0 | AD42: =X42 -> 0

Sheet ITEM 6
A1: DETAILED UNIT PRICE ANALYSIS
A3: PROJECT | E3: : | F3: ='POW COVER'!E9 -> Construction of Covered Pathway at City hall Entrance/Exit ( 29 SPAN, 3m length/span)
A4: Item No. | E4: : | F4: ='POW COVER'!B42 -> 1047(2)
A5: Description | E5: : | F5: ='POW COVER'!D42 -> Steel Works ( GIRT 2 ) ( 12.13m )
A6: Quantity | E6: : | F6: ='POW COVER'!M42 -> 17 | G6: ='POW COVER'!O42 -> sets | I6: sets
A7: Output Per Hour: | F7: 5 | G7: =""&G6&" per hour" -> sets per hour
AF8: hours
B9: Designation | N9: No. of Person | Q9: No. of Hours | T9: Houry Rate | X9: AMOUNT | AF9: =MAX(Q12:S15,Q20:S20) -> 0
A10: A. | B10: Labor
B12: a. Construction Foreman | X12: =T12*Q12*N12 -> 0
B13: b. Skilled Labor ( Welder ) | X13: =T13*Q13*O13 -> 0
B14: c. Unskilled Labor | X14: =T14*Q14*O14 -> 0
A16: Sub Total for A | X16: =SUM(X12:AC15) -> 0
B17: Name & Capacity | N17: No. of units | Q17: No. of Hours | T17: Houry Rate | X17: AMOUNT
A18: B. | B18: Equipment
A21: Sub Total for B | X21: =SUM(X20:AC20) -> 0
B22: Name & Specifications | N22: Units | Q22: Quantity | T22: Unit cost | X22: AMOUNT
A23: C. | B23: Materials
B25: Red Oxide | X25: =T25*Q25 -> 0
B26: Automotive paint ( silver ) | X26: =T26*Q26 -> 0
B27: paint thinner | X27: =T27*Q27 -> 0
B28: lacquer thinner | X28: =T28*Q28 -> 0
B29: paint brush ( 4" ) | X29: =T29*Q29 -> 0
B30: paint brush ( 2" ) | X30: =T30*Q30 -> 0
B31: paint brush ( 1" ) | X31: =T31*Q31 -> 0
X32: =T32*Q32 -> 0
A34: Sub-Total for C | X34: =SUM(X25:AC33) -> 0
